Workbook

Sheet Resultat
A1: Preleveur | B1: =[1]Elevage!A1 -> prelevement_id | C1: type_pvt | D1: hote | E1: echantillon_id | F1: date_prelevement | G1: projet | H1: Pos_neg | I1: PN_ESBL | J1: ESBL | K1: PN_CARBA | L1: CARBA | M1: isolat_ID | N1: amo_20 | O1: tgc_15 | P1: tic_75 | Q1: col_10 | R1: cox_5 | S1: amc_30 | T1: caz_10 | U1: gmn_10 | V1: amp_10 | W1: fep_30 | X1: etp_10 | Y1: ipm_10 | Z1: ofx_5 | AA1: cip_5 | AB1: sxt_25 | AC1: tet_30 | AD1: synergie | AE1: extraction | AF1: concentration_adn_ng_µL | AG1: sequençage | AH1: especes | AI1: st | AJ1: rapport | AL1: synergie
A2: Fayçal Khetim | B2: =[1]Elevage!A2 -> FK-001 | C2: Pédichiffe | D2: charcutier | E2: =B2&IF(D2="charcutier","M",IF(D2="cochette","F",""))&IF(C2="Pédichiffe","p",IF(C2="Ecouvillon","e",IF(C2="Feces","f",""))) -> FK-001Mp | F2: =_xlfn.XLOOKUP(B2,[1]Elevage!A:A,[1]Elevage!B:B) -> 46092 | G2: Eco-antibio2 | H2: =IF(AND(I2=0,K2=0),0,1) -> 0 | I2: 0 | J2: négatif | K2: 0 | L2: négatif | AJ2: 0 | AK2: 1 | AL2: synergie
A3: Fayçal Khetim | B3: =[1]Elevage!A3 -> FK-002 | C3: Pédichiffe | D3: charcutier | E3: =B3&IF(D3="charcutier","M",IF(D3="cochette","F",""))&IF(C3="Pédichiffe","p",IF(C3="Ecouvillon","e",IF(C3="Feces","f",""))) -> FK-002Mp | F3: =_xlfn.XLOOKUP(B3,[1]Elevage!A:A,[1]Elevage!B:B) -> 46092 | G3: =G2 -> Eco-antibio2 | H3: =IF(AND(I3=0,K3=0),0,1) -> 0 | I3: 0 | J3: négatif | K3: 0 | L3: négatif | AJ3: 0
A4: Fayçal Khetim | B4: =[1]Elevage!A4 -> FK-003 | C4: Pédichiffe | D4: cochette | E4: =B4&IF(D4="charcutier","M",IF(D4="cochette","F",""))&IF(C4="Pédichiffe","p",IF(C4="Ecouvillon","e",IF(C4="Feces","f",""))) -> FK-003Fp | F4: =_xlfn.XLOOKUP(B4,[1]Elevage!A:A,[1]Elevage!B:B) -> 46094 | G4: =G3 -> Eco-antibio2 | H4: =IF(AND(I4=0,K4=0),0,1) -> 0 | I4: 0 | J4: négatif | K4: 0 | L4: négatif | AJ4: 0
A5: Fayçal Khetim | B5: FK-003 | C5: Pédichiffe | D5: cochette | E5: =B5&IF(D5="charcutier","M",IF(D5="cochette","F",""))&IF(C5="Pédichiffe","p",IF(C5="Ecouvillon","e",IF(C5="Feces","f",""))) -> FK-003Fp | F5: =_xlfn.XLOOKUP(B5,[1]Elevage!A:A,[1]Elevage!B:B) -> 46094 | G5: =G4 -> Eco-antibio2 | H5: =IF(AND(I5=0,K5=0),0,1) -> 0 | I5: 0 | J5: négatif | K5: 0 | L5: négatif | AJ5: 0
A6: Fayçal Khetim | B6: FK-004 | C6: Pédichiffe | D6: charcutier | E6: =B6&IF(D6="charcutier","M",IF(D6="cochette","F",""))&IF(C6="Pédichiffe","p",IF(C6="Ecouvillon","e",IF(C6="Feces","f",""))) -> FK-004Mp | F6: =_xlfn.XLOOKUP(B6,[1]Elevage!A:A,[1]Elevage!B:B) -> 46099 | G6: =G5 -> Eco-antibio2 | H6: =IF(AND(I6=0,K6=0),0,1) -> 0 | I6: 0 | J6: négatif | K6: 0 | L6: négatif | AJ6: 1
A7: Fayçal Khetim | B7: FK-004 | C7: Pédichiffe | D7: cochette | E7: =B7&IF(D7="charcutier","M",IF(D7="cochette","F",""))&IF(C7="Pédichiffe","p",IF(C7="Ecouvillon","e",IF(C7="Feces","f",""))) -> FK-004Fp | F7: =_xlfn.XLOOKUP(B7,[1]Elevage!A:A,[1]Elevage!B:B) -> 46099 | G7: =G6 -> Eco-antibio2 | H7: =IF(AND(I7=0,K7=0),0,1) -> 1 | I7: 1 | J7: X | K7: 0 | L7: négatif | M7: 04FP.B | N7: 0 | O7: 20 | P7: 0 | Q7: 16 | R7: 0 | S7: 19 | T7: 26 | U7: 21 | V7: 0 | W7: 25 | X7: 34 | Y7: 31 | Z7: 28 | AA7: 31 | AB7: 0 | AC7: 0 | AD7: YES | AH7: klebsiella oxytoca | AI7: 40 | AJ7: 1
A8: Fayçal Khetim | B8: ="FK-"&TEXT(5+INT((ROW()-8)/3),"000") -> FK-005 | C8: Pédichiffe | D8: cochette | E8: =B8&IF(D8="charcutier","M",IF(D8="cochette","F",""))&IF(C8="Pédichiffe","p",IF(C8="Ecouvillon","e",IF(C8="Feces","f",""))) -> FK-005Fp | F8: =_xlfn.XLOOKUP(B8,[1]Elevage!A:A,[1]Elevage!B:B) -> 46106 | G8: =G7 -> Eco-antibio2 | H8: =IF(AND(I8=0,K8=0),0,1) -> 0 | I8: 0 | J8: négatif | K8: 0 | L8: négatif | AJ8: 0
A9: Fayçal Khetim | B9: ="FK-"&TEXT(5+INT((ROW()-8)/3),"000") -> FK-005 | C9: Pédichiffe | D9: charcutier | E9: =B9&IF(D9="charcutier","M",IF(D9="cochette","F",""))&IF(C9="Pédichiffe","p",IF(C9="Ecouvillon","e",IF(C9="Feces","f",""))) -> FK-005Mp | F9: =_xlfn.XLOOKUP(B9,[1]Elevage!A:A,[1]Elevage!B:B) -> 46106 | G9: =G8 -> Eco-antibio2 | H9: =IF(AND(I9=0,K9=0),0,1) -> 0 | I9: 0 | J9: négatif | K9: 0 | L9: négatif | AJ9: 0
A10: Fayçal Khetim | B10: ="FK-"&TEXT(5+INT((ROW()-8)/3),"000") -> FK-005 | C10: Ecouvillon | D10: cochette | E10: =B10&IF(D10="charcutier","M",IF(D10="cochette","F",""))&IF(C10="Pédichiffe","p",IF(C10="Ecouvillon","e",IF(C10="Feces","f",""))) -> FK-005Fe | F10: =_xlfn.XLOOKUP(B10,[1]Elevage!A:A,[1]Elevage!B:B) -> 46106 | G10: =G9 -> Eco-antibio2 | H10: =IF(AND(I10=0,K10=0),0,1) -> 0 | I10: 0 | J10: négatif | K10: 0 | L10: négatif | AJ10: 0
A11: Fayçal Khetim | B11: ="FK-"&TEXT(5+INT((ROW()-8)/3),"000") -> FK-006 | C11: Pédichiffe | D11: cochette | E11: =B11&IF(D11="charcutier","M",IF(D11="cochette","F",""))&IF(C11="Pédichiffe","p",IF(C11="Ecouvillon","e",IF(C11="Feces","f",""))) -> FK-006Fp | F11: =_xlfn.XLOOKUP(B11,[1]Elevage!A:A,[1]Elevage!B:B) -> 46106 | G11: =G10 -> Eco-antibio2 | H11: =IF(AND(I11=0,K11=0),0,1) -> 1 | I11: 1 | J11: x | K11: 0 | L11: négatif | M11: 06FP.R | N11: 0 | O11: 24 | P11: 0 | Q11: 16 | R11: 0 | S11: 21 | T11: 16 | U11: 21 | V11: 0 | W11: 19 | X11: 33 | Y11: 32 | Z11: 20 | AA11: 24 | AB11: 34 | AC11: 26 | AD11: YES | AH11: e-coli | AI11: 3268 | AJ11: 1
A12: Fayçal Khetim | B12: ="FK-"&TEXT(5+INT((ROW()-8)/3),"000") -> FK-006 | C12: Pédichiffe | D12: charcutier | E12: =B12&IF(D12="charcutier","M",IF(D12="cochette","F",""))&IF(C12="Pédichiffe","p",IF(C12="Ecouvillon","e",IF(C12="Feces","f",""))) -> FK-006Mp | F12: =_xlfn.XLOOKUP(B12,[1]Elevage!A:A,[1]Elevage!B:B) -> 46106 | G12: =G11 -> Eco-antibio2 | H12: =IF(AND(I12=0,K12=0),0,1) -> 0 | I12: 0 | J12: négatif | K12: 0 | L12: négatif | AJ12: 1
A13: Fayçal Khetim | B13: ="FK-"&TEXT(5+INT((ROW()-8)/3),"000") -> FK-006 | C13: Ecouvillon | D13: cochette | E13: =B13&IF(D13="charcutier","M",IF(D13="cochette","F",""))&IF(C13="Pédichiffe","p",IF(C13="Ecouvillon","e",IF(C13="Feces","f",""))) -> FK-006Fe | F13: =_xlfn.XLOOKUP(B13,[1]Elevage!A:A,[1]Elevage!B:B) -> 46106 | G13: =G12 -> Eco-antibio2 | H13: =IF(AND(I13=0,K13=0),0,1) -> 0 | I13: 0 | J13: négatif | K13: 0 | L13: négatif | AJ13: 1
A14: Fayçal Khetim | B14: ="FK-"&TEXT(5+INT((ROW()-8)/3),"000") -> FK-007 | C14: Pédichiffe | D14: cochette | E14: =B14&IF(D14="charcutier","M",IF(D14="cochette","F",""))&IF(C14="Pédichiffe","p",IF(C14="Ecouvillon","e",IF(C14="Feces","f",""))) -> FK-007Fp | F14: =_xlfn.XLOOKUP(B14,[1]Elevage!A:A,[1]Elevage!B:B) -> 46111 | G14: =G13 -> Eco-antibio2 | H14: =IF(AND(I14=0,K14=0),0,1) -> 0 | I14: 0 | J14: négatif | K14: 0 | L14: négatif | AJ14: 0
A15: Fayçal Khetim | B15: ="FK-"&TEXT(5+INT((ROW()-8)/3),"000") -> FK-007 | C15: Pédichiffe | D15: charcutier | E15: =B15&IF(D15="charcutier","M",IF(D15="cochette","F",""))&IF(C15="Pédichiffe","p",IF(C15="Ecouvillon","e",IF(C15="Feces","f",""))) -> FK-007Mp | F15: =_xlfn.XLOOKUP(B15,[1]Elevage!A:A,[1]Elevage!B:B) -> 46111 | G15: =G14 -> Eco-antibio2 | H15: =IF(AND(I15=0,K15=0),0,1) -> 0 | I15: 0 | J15: négatif | K15: 0 | L15: négatif | AJ15: 0
A16: Fayçal Khetim | B16: ="FK-"&TEXT(5+INT((ROW()-8)/3),"000") -> FK-007 | C16: Ecouvillon | D16: cochette | E16: =B16&IF(D16="charcutier","M",IF(D16="cochette","F",""))&IF(C16="Pédichiffe","p",IF(C16="Ecouvillon","e",IF(C16="Feces","f",""))) -> FK-007Fe | F16: =_xlfn.XLOOKUP(B16,[1]Elevage!A:A,[1]Elevage!B:B) -> 46111 | G16: =G15 -> Eco-antibio2 | H16: =IF(AND(I16=0,K16=0),0,1) -> 0 | I16: 0 | J16: négatif | K16: 0 | L16: négatif | AJ16: 0
A17: Fayçal Khetim | B17: ="FK-"&TEXT(5+INT((ROW()-8)/3),"000") -> FK-008 | C17: Pédichiffe | D17: cochette | E17: =B17&IF(D17="charcutier","M",IF(D17="cochette","F",""))&IF(C17="Pédichiffe","p",IF(C17="Ecouvillon","e",IF(C17="Feces","f",""))) -> FK-008Fp | F17: =_xlfn.XLOOKUP(B17,[1]Elevage!A:A,[1]Elevage!B:B) -> 46111 | G17: =G16 -> Eco-antibio2 | H17: =IF(AND(I17=0,K17=0),0,1) -> 0 | I17: 0 | J17: négatif | K17: 0 | L17: négatif | AJ17: 0
A18: Fayçal Khetim | B18: ="FK-"&TEXT(5+INT((ROW()-8)/3),"000") -> FK-008 | C18: Pédichiffe | D18: charcutier | E18: =B18&IF(D18="charcutier","M",IF(D18="cochette","F",""))&IF(C18="Pédichiffe","p",IF(C18="Ecouvillon","e",IF(C18="Feces","f",""))) -> FK-008Mp | F18: =_xlfn.XLOOKUP(B18,[1]Elevage!A:A,[1]Elevage!B:B) -> 46111 | G18: =G17 -> Eco-antibio2 | H18: =IF(AND(I18=0,K18=0),0,1) -> 0 | I18: 0 | J18: négatif | K18: 0 | L18: négatif | AJ18: 0
A19: Fayçal Khetim | B19: ="FK-"&TEXT(5+INT((ROW()-8)/3),"000") -> FK-008 | C19: Ecouvillon | D19: cochette | E19: =B19&IF(D19="charcutier","M",IF(D19="cochette","F",""))&IF(C19="Pédichiffe","p",IF(C19="Ecouvillon","e",IF(C19="Feces","f",""))) -> FK-008Fe | F19: =_xlfn.XLOOKUP(B19,[1]Elevage!A:A,[1]Elevage!B:B) -> 46111 | G19: =G18 -> Eco-antibio2 | H19: =IF(AND(I19=0,K19=0),0,1) -> 0 | I19: 0 | J19: négatif | K19: 0 | L19: négatif | AJ19: 0
A20: Fayçal Khetim | B20: ="FK-"&TEXT(5+INT((ROW()-8)/3),"000") -> FK-009 | C20: Pédichiffe | D20: cochette | E20: =B20&IF(D20="charcutier","M",IF(D20="cochette","F",""))&IF(C20="Pédichiffe","p",IF(C20="Ecouvillon","e",IF(C20="Feces","f",""))) -> FK-009Fp | F20: =_xlfn.XLOOKUP(B20,[1]Elevage!A:A,[1]Elevage!B:B) -> 46111 | G20: =G19 -> Eco-antibio2 | H20: =IF(AND(I20=0,K20=0),0,1) -> 0 | I20: 0 | J20: négatif | K20: 0 | L20: négatif | AH20: Enterobacter cloacae | AJ20: 0
A21: Fayçal Khetim | B21: ="FK-"&TEXT(5+INT((ROW()-8)/3),"000") -> FK-009 | C21: Pédichiffe | D21: charcutier | E21: =B21&IF(D21="charcutier","M",IF(D21="cochette","F",""))&IF(C21="Pédichiffe","p",IF(C21="Ecouvillon","e",IF(C21="Feces","f",""))) -> FK-009Mp | F21: =_xlfn.XLOOKUP(B21,[1]Elevage!A:A,[1]Elevage!B:B) -> 46111 | G21: =G20 -> Eco-antibio2 | H21: =IF(AND(I21=0,K21=0),0,1) -> 0 | I21: 0 | J21: négatif | K21: 0 | L21: négatif | AJ21: 0
A22: Fayçal Khetim | B22: ="FK-"&TEXT(5+INT((ROW()-8)/3),"000") -> FK-009 | C22: Ecouvillon | D22: cochette | E22: =B22&IF(D22="charcutier","M",IF(D22="cochette","F",""))&IF(C22="Pédichiffe","p",IF(C22="Ecouvillon","e",IF(C22="Feces","f",""))) -> FK-009Fe | F22: =_xlfn.XLOOKUP(B22,[1]Elevage!A:A,[1]Elevage!B:B) -> 46111 | G22: =G21 -> Eco-antibio2 | H22: =IF(AND(I22=0,K22=0),0,1) -> 0 | I22: 0 | J22: négatif | K22: 0 | L22: négatif | AJ22: 0
A23: Fayçal Khetim | B23: ="FK-"&TEXT(5+INT((ROW()-8)/3),"000") -> FK-010 | C23: Pédichiffe | D23: cochette | E23: =B23&IF(D23="charcutier","M",IF(D23="cochette","F",""))&IF(C23="Pédichiffe","p",IF(C23="Ecouvillon","e",IF(C23="Feces","f",""))) -> FK-010Fp | F23: =_xlfn.XLOOKUP(B23,[1]Elevage!A:A,[1]Elevage!B:B) -> 46111 | G23: =G22 -> Eco-antibio2 | H23: =IF(AND(I23=0,K23=0),0,1) -> 0 | I23: 0 | J23: négatif | K23: 0 | L23: négatif | AJ23: 0
A24: Fayçal Khetim | B24: ="FK-"&TEXT(5+INT((ROW()-8)/3),"000") -> FK-010 | C24: Pédichiffe | D24: charcutier | E24: =B24&IF(D24="charcutier","M",IF(D24="cochette","F",""))&IF(C24="Pédichiffe","p",IF(C24="Ecouvillon","e",IF(C24="Feces","f",""))) -> FK-010Mp | F24: =_xlfn.XLOOKUP(B24,[1]Elevage!A:A,[1]Elevage!B:B) -> 46111 | G24: =G23 -> Eco-antibio2 | H24: =IF(AND(I24=0,K24=0),0,1) -> 0 | I24: 0 | J24: négatif | K24: 0 | L24: négatif | AJ24: 0
A25: Fayçal Khetim | B25: ="FK-"&TEXT(5+INT((ROW()-8)/3),"000") -> FK-010 | C25: Ecouvillon | D25: cochette | E25: =B25&IF(D25="charcutier","M",IF(D25="cochette","F",""))&IF(C25="Pédichiffe","p",IF(C25="Ecouvillon","e",IF(C25="Feces","f",""))) -> FK-010Fe | F25: =_xlfn.XLOOKUP(B25,[1]Elevage!A:A,[1]Elevage!B:B) -> 46111 | G25: =G24 -> Eco-antibio2 | H25: =IF(AND(I25=0,K25=0),0,1) -> 0 | I25: 0 | J25: négatif | K25: 0 | L25: négatif | AJ25: 0
A26: Fayçal Khetim | B26: ="FK-"&TEXT(5+INT((ROW()-8)/3),"000") -> FK-011 | C26: Pédichiffe | D26: cochette | E26: =B26&IF(D26="charcutier","M",IF(D26="cochette","F",""))&IF(C26="Pédichiffe","p",IF(C26="Ecouvillon","e",IF(C26="Feces","f",""))) -> FK-011Fp | F26: =_xlfn.XLOOKUP(B26,[1]Elevage!A:A,[1]Elevage!B:B) -> 46112 | G26: =G25 -> Eco-antibio2 | H26: =IF(AND(I26=0,K26=0),0,1) -> 0 | I26: 0 | J26: négatif | K26: 0 | L26: négatif | AJ26: 0
A27: Fayçal Khetim | B27: ="FK-"&TEXT(5+INT((ROW()-8)/3),"000") -> FK-011 | C27: Pédichiffe | D27: charcutier | E27: =B27&IF(D27="charcutier","M",IF(D27="cochette","F",""))&IF(C27="Pédichiffe","p",IF(C27="Ecouvillon","e",IF(C27="Feces","f",""))) -> FK-011Mp | F27: =_xlfn.XLOOKUP(B27,[1]Elevage!A:A,[1]Elevage!B:B) -> 46112 | G27: =G26 -> Eco-antibio2 | H27: =IF(AND(I27=0,K27=0),0,1) -> 0 | I27: 0 | J27: négatif | K27: 0 | L27: négatif | AJ27: 0
A28: Fayçal Khetim | B28: ="FK-"&TEXT(5+INT((ROW()-8)/3),"000") -> FK-011 | C28: Ecouvillon | D28: cochette | E28: =B28&IF(D28="charcutier","M",IF(D28="cochette","F",""))&IF(C28="Pédichiffe","p",IF(C28="Ecouvillon","e",IF(C28="Feces","f",""))) -> FK-011Fe | F28: =_xlfn.XLOOKUP(B28,[1]Elevage!A:A,[1]Elevage!B:B) -> 46112 | G28: =G27 -> Eco-antibio2 | H28: =IF(AND(I28=0,K28=0),0,1) -> 0 | I28: 0 | J28: négatif | K28: 0 | L28: négatif | AJ28: 0
A29: Fayçal Khetim | B29: ="FK-"&TEXT(5+INT((ROW()-8)/3),"000") -> FK-012 | C29: Pédichiffe | D29: cochette | E29: =B29&IF(D29="charcutier","M",IF(D29="cochette","F",""))&IF(C29="Pédichiffe","p",IF(C29="Ecouvillon","e",IF(C29="Feces","f",""))) -> FK-012Fp | F29: =_xlfn.XLOOKUP(B29,[1]Elevage!A:A,[1]Elevage!B:B) -> 46112 | G29: =G28 -> Eco-antibio2 | H29: =IF(AND(I29=0,K29=0),0,1) -> 0 | I29: 0 | J29: négatif | K29: 0 | L29: négatif | AJ29: 0
A30: Fayçal Khetim | B30: ="FK-"&TEXT(5+INT((ROW()-8)/3),"000") -> FK-012 | C30: Pédichiffe | D30: charcutier | E30: =B30&IF(D30="charcutier","M",IF(D30="cochette","F",""))&IF(C30="Pédichiffe","p",IF(C30="Ecouvillon","e",IF(C30="Feces","f",""))) -> FK-012Mp | F30: =_xlfn.XLOOKUP(B30,[1]Elevage!A:A,[1]Elevage!B:B) -> 46112 | G30: =G29 -> Eco-antibio2 | H30: =IF(AND(I30=0,K30=0),0,1) -> 0 | I30: 0 | J30: négatif | K30: 0 | L30: négatif | AJ30: 0
A31: Fayçal Khetim | B31: ="FK-"&TEXT(5+INT((ROW()-8)/3),"000") -> FK-012 | C31: Ecouvillon | D31: cochette | E31: =B31&IF(D31="charcutier","M",IF(D31="cochette","F",""))&IF(C31="Pédichiffe","p",IF(C31="Ecouvillon","e",IF(C31="Feces","f",""))) -> FK-012Fe | F31: =_xlfn.XLOOKUP(B31,[1]Elevage!A:A,[1]Elevage!B:B) -> 46112 | G31: =G30 -> Eco-antibio2 | H31: =IF(AND(I31=0,K31=0),0,1) -> 0 | I31: 0 | J31: négatif | K31: 0 | L31: négatif | AJ31: 0
A32: Fayçal Khetim | B32: ="FK-"&TEXT(5+INT((ROW()-8)/3),"000") -> FK-013 | C32: Pédichiffe | D32: cochette | E32: =B32&IF(D32="charcutier","M",IF(D32="cochette","F",""))&IF(C32="Pédichiffe","p",IF(C32="Ecouvillon","e",IF(C32="Feces","f",""))) -> FK-013Fp | F32: =_xlfn.XLOOKUP(B32,[1]Elevage!A:A,[1]Elevage!B:B) -> 46112 | G32: =G31 -> Eco-antibio2 | H32: =IF(AND(I32=0,K32=0),0,1) -> 1 | I32: 1 | J32: x | K32: 0 | L32: négatif | M32: 13FP.B | N32: 0 | O32: 25 | P32: 16 | Q32: 18 | R32: 0 | S32: 0 | T32: 0 | U32: 28 | V32: 0 | W32: 37 | X32: 28 | Y32: 30 | Z32: 34 | AA32: 40 | AB32: 38 | AC32: 26 | AD32: NO | AH32: Enterobacter cloacae | AI32: 14 | AJ32: 1
A33: Fayçal Khetim | B33: ="FK-"&TEXT(5+INT((ROW()-8)/3),"000") -> FK-013 | C33: Pédichiffe | D33: charcutier | E33: =B33&IF(D33="charcutier","M",IF(D33="cochette","F",""))&IF(C33="Pédichiffe","p",IF(C33="Ecouvillon","e",IF(C33="Feces","f",""))) -> FK-013Mp | F33: =_xlfn.XLOOKUP(B33,[1]Elevage!A:A,[1]Elevage!B:B) -> 46112 | G33: =G32 -> Eco-antibio2 | H33: =IF(AND(I33=0,K33=0),0,1) -> 0 | I33: 0 | J33: négatif | K33: 0 | L33: négatif | AJ33: 1
A34: Fayçal Khetim | B34: ="FK-"&TEXT(5+INT((ROW()-8)/3),"000") -> FK-013 | C34: Ecouvillon | D34: cochette | E34: =B34&IF(D34="charcutier","M",IF(D34="cochette","F",""))&IF(C34="Pédichiffe","p",IF(C34="Ecouvillon","e",IF(C34="Feces","f",""))) -> FK-013Fe | F34: =_xlfn.XLOOKUP(B34,[1]Elevage!A:A,[1]Elevage!B:B) -> 46112 | G34: =G33 -> Eco-antibio2 | H34: =IF(AND(I34=0,K34=0),0,1) -> 0 | I34: 0 | J34: négatif | K34: 0 | L34: négatif | AJ34: 1
A35: Fayçal Khetim | B35: ="FK-"&TEXT(5+INT((ROW()-8)/3),"000") -> FK-014 | C35: Pédichiffe | D35: cochette | E35: =B35&IF(D35="charcutier","M",IF(D35="cochette","F",""))&IF(C35="Pédichiffe","p",IF(C35="Ecouvillon","e",IF(C35="Feces","f",""))) -> FK-014Fp | F35: =_xlfn.XLOOKUP(B35,[1]Elevage!A:A,[1]Elevage!B:B) -> 46112 | G35: =G34 -> Eco-antibio2 | H35: =IF(AND(I35=0,K35=0),0,1) -> 0 | I35: 0 | J35: négatif | K35: 0 | L35: négatif | AJ35: 1
A36: Fayçal Khetim | B36: ="FK-"&TEXT(5+INT((ROW()-8)/3),"000") -> FK-014 | C36: Pédichiffe | D36: charcutier | E36: =B36&IF(D36="charcutier","M",IF(D36="cochette","F",""))&IF(C36="Pédichiffe","p",IF(C36="Ecouvillon","e",IF(C36="Feces","f",""))) -> FK-014Mp | F36: =_xlfn.XLOOKUP(B36,[1]Elevage!A:A,[1]Elevage!B:B) -> 46112 | G36: =G35 -> Eco-antibio2 | H36: =IF(AND(I36=0,K36=0),0,1) -> 0 | I36: 0 | J36: négatif | K36: 0 | L36: négatif | AH36: X | AI36: 0 | AJ36: 1
A37: Fayçal Khetim | B37: ="FK-"&TEXT(5+INT((ROW()-8)/3),"000") -> FK-014 | C37: Ecouvillon | D37: cochette | E37: =B37&IF(D37="charcutier","M",IF(D37="cochette","F",""))&IF(C37="Pédichiffe","p",IF(C37="Ecouvillon","e",IF(C37="Feces","f",""))) -> FK-014Fe | F37: =_xlfn.XLOOKUP(B37,[1]Elevage!A:A,[1]Elevage!B:B) -> 46112 | G37: =G36 -> Eco-antibio2 | H37: =IF(AND(I37=0,K37=0),0,1) -> 0 | I37: 0 | J37: négatif | K37: 0 | L37: négatif | AJ37: 1
A38: Fayçal Khetim | B38: ="FK-"&TEXT(5+INT((ROW()-8)/3),"000") -> FK-015 | C38: Pédichiffe | D38: cochette | E38: =B38&IF(D38="charcutier","M",IF(D38="cochette","F",""))&IF(C38="Pédichiffe","p",IF(C38="Ecouvillon","e",IF(C38="Feces","f",""))) -> FK-015Fp | F38: =_xlfn.XLOOKUP(B38,[1]Elevage!A:A,[1]Elevage!B:B) -> 46113 | G38: =G37 -> Eco-antibio2 | H38: =IF(AND(I38=0,K38=0),0,1) -> 0 | I38: 0 | J38: négatif | K38: 0 | L38: négatif | AJ38: 0
A39: Fayçal Khetim | B39: ="FK-"&TEXT(5+INT((ROW()-8)/3),"000") -> FK-015 | C39: Pédichiffe | D39: charcutier | E39: =B39&IF(D39="charcutier","M",IF(D39="cochette","F",""))&IF(C39="Pédichiffe","p",IF(C39="Ecouvillon","e",IF(C39="Feces","f",""))) -> FK-015Mp | F39: =_xlfn.XLOOKUP(B39,[1]Elevage!A:A,[1]Elevage!B:B) -> 46113 | G39: =G38 -> Eco-antibio2 | H39: =IF(AND(I39=0,K39=0),0,1) -> 0 | I39: 0 | J39: négatif | K39: 0 | L39: négatif | AJ39: 0
A40: Fayçal Khetim | B40: ="FK-"&TEXT(5+INT((ROW()-8)/3),"000") -> FK-015 | C40: Ecouvillon | D40: cochette | E40: =B40&IF(D40="charcutier","M",IF(D40="cochette","F",""))&IF(C40="Pédichiffe","p",IF(C40="Ecouvillon","e",IF(C40="Feces","f",""))) -> FK-015Fe | F40: =_xlfn.XLOOKUP(B40,[1]Elevage!A:A,[1]Elevage!B:B) -> 46113 | G40: =G39 -> Eco-antibio2 | H40: =IF(AND(I40=0,K40=0),0,1) -> 0 | I40: 0 | J40: négatif | K40: 0 | L40: négatif | AJ40: 0
...

Sheet Elevage
A1: prelevement_id | B1: date_prelevement | C1: projet | D1: code | E1: code_eleveur | F1: elevage | G1: eleveur | H1: elevage_type | I1: Preleveur | J1: adresse | K1: ile | L1: ville | M1: cp | N1: Statut | O1: lat | P1: long | Q1: contact | R1: telephone | S1: mail | T1: organisation | U1: num_batiment | V1: remarques | W1: nature_pvt | X1: hote | Y1: sexe | Z1: age | AA1: lieu_de_vie | AB1: contact_autre_animaux | AE1: code
A2: FK-001 | B2: 46092 | C2: Eco-antibio2 | D2: 40 | E2: {=INDEX(AAA!D:D,AE2)} -> 98121196 | F2: EARL BOIS DE SENTEUR | G2: Hoareau Frederic | H2: Naisseur-engraisseur | I2: Fayçal Khetim | J2: {=INDEX(AAA!E:E,AE2)} -> 18 CHEMIN DARDANELLE | K2: La réunion | L2: {=INDEX(AAA!C:C,AE3)} -> SAINT JOSEPH | M2: {=INDEX(AAA!G:G,AE2)} -> 97480 | N2: {=INDEX(AAA!B:B,AE2)} -> C | S2: frederic.hoareau333@gmail.com | AE2: 40
A3: FK-002 | B3: 46092 | C3: =C2 -> Eco-antibio2 | D3: 72 | E3: {=INDEX(AAA!D:D,AE3)} -> 98312056 | F3: EARL LA TITOU FARM | G3: Huet andre | H3: Naisseur-engraisseur | I3: Fayçal Khetim | J3: {=INDEX(AAA!E:E,AE3)} -> 3 CHEMIN BOIS D HOSTO | K3: La réunion | L3: {=INDEX(AAA!C:C,AE3)} -> SAINT JOSEPH | M3: {=INDEX(AAA!G:G,AE3)} -> 97480 | N3: {=INDEX(AAA!B:B,AE3)} -> C | S3: earl-latitoufarm@outlook.fr | AE3: 72
A4: FK-003 | B4: 46094 | C4: =C3 -> Eco-antibio2 | D4: 48 | E4: {=INDEX(AAA!D:D,AE4)} -> 98322112 | F4: EARL CHEMIN GRAND PERE | G4: Emmanuelle Picard | H4: Naisseur-engraisseur | I4: Fayçal Khetim | J4: {=INDEX(AAA!E:E,AE4)} -> 107 CHEMIN GRAND PERE | K4: La réunion | L4: {=INDEX(AAA!C:C,AE4)} -> SAINT PIERRE / PETITE ILE | M4: {=INDEX(AAA!G:G,AE4)} -> 97410 | N4: {=INDEX(AAA!B:B,AE4)} -> C | S4: =AAA!L48 -> picard.emmanuelle974@gmail.com | AE4: 48
A5: FK-004 | B5: 46099 | C5: =C4 -> Eco-antibio2 | D5: 120 | E5: {=INDEX(AAA!D:D,AE5)} -> 98016602 | F5: HOARAU JONATHAN | G5: Hoarau jonathan | H5: Naisseur-engraisseur | I5: Fayçal Khetim | J5: {=INDEX(AAA!E:E,AE5)} -> 256 CHEMIN GRAND PÈRE | K5: La réunion | L5: {=INDEX(AAA!C:C,AE5)} -> SAINT PIERRE / PETITE ILE | M5: {=INDEX(AAA!G:G,AE5)} -> 97410 | N5: {=INDEX(AAA!B:B,AE5)} -> C | S5: =AAA!L120 -> nathan490001@gmail.com | AE5: 120
A6: FK-005 | B6: 46106 | C6: =C5 -> Eco-antibio2 | D6: 154 | E6: {=INDEX(AAA!D:D,AE6)} -> 98214350 | F6: =AAA!A$154 -> SCEA AMELIA (ex:EARL AMELIA) | G6: Lépinay Anne-Gaëlle | H6: Naisseur-engraisseur | I6: Fayçal Khetim | J6: {=INDEX(AAA!E:E,AE6)} -> 12 i LIGNE CHEVALIER | K6: La réunion | L6: {=INDEX(AAA!C:C,AE6)} -> ETANG SALE/SAINT LOUIS | M6: {=INDEX(AAA!G:G,AE6)} -> 97421 | N6: {=INDEX(AAA!B:B,AE6)} -> C | S6: sceaamelia@gmail.com | AE6: 154
A7: FK-006 | B7: 46106 | C7: =C6 -> Eco-antibio2 | D7: 51 | E7: {=INDEX(AAA!D:D,AE7)} -> 98214002 | F7: =AAA!A$51 -> EARL DE BELLE VUE | G7: Maieu Désiré | H7: Naisseur-engraisseur | I7: Fayçal Khetim | J7: {=INDEX(AAA!E:E,AE7)} -> 30 CHEMIN BELLEVUE | K7: La réunion | L7: {=INDEX(AAA!C:C,AE7)} -> ETANG SALE/SAINT LOUIS | M7: {=INDEX(AAA!G:G,AE7)} -> 97450 | N7: {=INDEX(AAA!B:B,AE7)} -> C | S7: =AAA!L$51 -> joke450@hotmail.fr | AE7: 51
A8: FK-007 | B8: 46111 | C8: =C7 -> Eco-antibio2 | D8: 90 | E8: {=INDEX(AAA!D:D,AE8)} -> 98101005 | F8: =AAA!A$90 -> EARL LES TROIS PETITS COCHONS (EX:HOAREAU GEORGES MARIE) | G8: Nicole Florian | H8: Naisseur-engraisseur | I8: Fayçal Khetim | J8: {=INDEX(AAA!E:E,AE8)} -> 25C CHEMIN MAURER | K8: La réunion | L8: {=INDEX(AAA!C:C,AE8)} -> AVIRONS/ SAINT LEU | M8: {=INDEX(AAA!G:G,AE8)} -> 97425 | N8: {=INDEX(AAA!B:B,AE8)} -> C | S8: admi.3pc@gmail.com | AE8: 90
A9: FK-008 | B9: 46111 | C9: =C8 -> Eco-antibio2 | D9: 82 | E9: {=INDEX(AAA!D:D,AE9)} -> 98101022 | F9: =AAA!A$82 -> EARL LES CAPUCINES EX RIVIERE GINETTE MARIE ROLAND | G9: Rivière Anicia | H9: Naisseur-engraisseur | I9: Fayçal Khetim | J9: {=INDEX(AAA!E:E,AE9)} -> 6 TERRASSE DE BOIS DE NEFLES | K9: La réunion | L9: {=INDEX(AAA!C:C,AE9)} -> AVIRONS/ SAINT LEU | M9: {=INDEX(AAA!G:G,AE9)} -> 97425 | N9: {=INDEX(AAA!B:B,AE9)} -> C | S9: =AAA!L$82 -> ani.riviere@hotmail.fr | AE9: =D9 -> 82
A10: FK-009 | B10: 46111 | C10: =C9 -> Eco-antibio2 | D10: 176 | E10: {=INDEX(AAA!D:D,AE10)} -> 98001166 | F10: =AAA!A$176 -> VATEL BERNARD | G10: Vatel Angelique | H10: Naisseur-engraisseur | I10: Fayçal Khetim | J10: {=INDEX(AAA!E:E,AE10)} -> 8 ROUTE DES VACOAS | K10: La réunion | L10: {=INDEX(AAA!C:C,AE10)} -> AVIRONS/ SAINT LEU | M10: {=INDEX(AAA!G:G,AE10)} -> 97425 | N10: {=INDEX(AAA!B:B,AE10)} -> C | S10: =AAA!L$176 -> bernardvatel@orange.fr | AE10: =D10 -> 176
A11: FK-010 | B11: 46111 | C11: =C10 -> Eco-antibio2 | D11: 39 | E11: {=INDEX(AAA!D:D,AE11)} -> 98001055 | F11: EARL BELLECOMBE | G11: Sartre jean | H11: Naisseur-engraisseur | I11: Fayçal Khetim | J11: {=INDEX(AAA!E:E,AE11)} -> 9 ROUTE DU STADE | K11: La réunion | L11: {=INDEX(AAA!C:C,AE11)} -> AVIRONS/ SAINT LEU | M11: {=INDEX(AAA!G:G,AE11)} -> 97425 | N11: {=INDEX(AAA!B:B,AE11)} -> C | S11: =AAA!L$39 -> bellecombe.sartre@gmail.com | AE11: =D11 -> 39
A12: FK-011 | B12: 46112 | C12: =C11 -> Eco-antibio2 | D12: 87 | E12: {=INDEX(AAA!D:D,AE12)} -> 98213102 | F12: =AAA!A$87 -> EARL LES LETCHIS | G12: Etienne Florian | H12: Naisseur-engraisseur | I12: Fayçal Khetim | J12: {=INDEX(AAA!E:E,AE12)} -> 18 ALLEE DES LETCHIS | K12: La réunion | L12: {=INDEX(AAA!C:C,AE12)} -> AVIRONS/ SAINT LEU | M12: {=INDEX(AAA!G:G,AE12)} -> 97424 | N12: {=INDEX(AAA!B:B,AE12)} -> C | S12: florianetienne974@gmail.com | AE12: =D12 -> 87
A13: FK-012 | B13: 46112 | C13: =C12 -> Eco-antibio2 | D13: 43 | E13: {=INDEX(AAA!D:D,AE13)} -> 98001167 | F13: =AAA!A$43 -> EARL CALTEAU | G13: Calteau Georges | H13: Naisseur-engraisseur | I13: Fayçal Khetim | J13: {=INDEX(AAA!E:E,AE13)} -> 35 CHEMIN DOZENVAL | K13: La réunion | L13: {=INDEX(AAA!C:C,AE13)} -> AVIRONS/ SAINT LEU | M13: {=INDEX(AAA!G:G,AE13)} -> 97425 | N13: {=INDEX(AAA!B:B,AE13)} -> C | S13: =AAA!L$43 -> georges.calteau@wanadoo.fr | AE13: =D13 -> 43
A14: FK-013 | B14: 46112 | C14: =C13 -> Eco-antibio2 | D14: 67 | E14: {=INDEX(AAA!D:D,AE14)} -> 98001038 | F14: =AAA!A$67 -> EARL KERBEL (ex GAEC KERBEL) | G14: Calteau Georges | H14: Naisseur-engraisseur | I14: Fayçal Khetim | J14: {=INDEX(AAA!E:E,AE14)} -> 117 CHEMIN KERBEL | K14: La réunion | L14: {=INDEX(AAA!C:C,AE14)} -> AVIRONS/ SAINT LEU | M14: {=INDEX(AAA!G:G,AE14)} -> 97425 | N14: {=INDEX(AAA!B:B,AE14)} -> C | S14: =AAA!L$43 -> georges.calteau@wanadoo.fr | AE14: =D14 -> 67
A15: FK-014 | B15: 46112 | C15: =C14 -> Eco-antibio2 | D15: 104 | E15: {=INDEX(AAA!D:D,AE15)} -> 98313032 | F15: =AAA!A$104 -> EARL TOUT LE BON (ex:LE BORGNE THIERRY) | G15: Rivière Marick | H15: Naisseur-engraisseur | I15: Fayçal Khetim | J15: {=INDEX(AAA!E:E,AE15)} -> 5. CHEMIN TAN ROUGE LE PLATE | K15: La réunion | L15: {=INDEX(AAA!C:C,AE15)} -> AVIRONS/ SAINT LEU | M15: {=INDEX(AAA!G:G,AE15)} -> 97424 | N15: {=INDEX(AAA!B:B,AE15)} -> IPA | S15: earltoutlebon@hotmail.com | AE15: =D15 -> 104
A16: FK-015 | B16: 46113 | C16: =C15 -> Eco-antibio2 | D16: 69 | E16: {=INDEX(AAA!D:D,AE16)} -> 98213167 | F16: =AAA!A$69 -> EARL LA FERME DU COIN TRANQUILLE | G16: Begue Jeremy | H16: Naisseur-engraisseur | I16: Fayçal Khetim | J16: {=INDEX(AAA!E:E,AE16)} -> 19ter CHEMIN TAN ROUGE | K16: La réunion | L16: {=INDEX(AAA!C:C,AE16)} -> AVIRONS/ SAINT LEU | M16: {=INDEX(AAA!G:G,AE16)} -> 97424 | N16: {=INDEX(AAA!B:B,AE16)} -> C | S16: =AAA!L$69 -> lafermeducointranquille@orange.fr | AE16: =D16 -> 69
A17: FK-016 | B17: 46113 | C17: =C16 -> Eco-antibio2 | D17: 81 | E17: {=INDEX(AAA!D:D,AE17)} -> 98023154 | F17: EARL LES CALUMETS | G17: Nourry Aldo | H17: Naisseur-engraisseur | I17: Fayçal Khetim | J17: {=INDEX(AAA!E:E,AE17)} -> 201 CHEMIN MAROCAIN | K17: La réunion | L17: {=INDEX(AAA!C:C,AE17)} -> TROIS BASSINS/ SAINT PAUL | M17: {=INDEX(AAA!G:G,AE17)} -> 97426 | N17: {=INDEX(AAA!B:B,AE17)} -> C | S17: =AAA!L$81 -> earl.lescalumets@sfr.fr | AE17: =D17 -> 81
A18: FK-017 | B18: 46113 | C18: =C17 -> Eco-antibio2 | D18: 26 | E18: {=INDEX(AAA!D:D,AE18)} -> 98715202 | F18: =AAA!A$26 -> CRESCENCE GUITO | G18: Crescence vivien | H18: Naisseur-engraisseur | I18: Fayçal Khetim | J18: {=INDEX(AAA!E:E,AE18)} -> 130 CHEMIN DE LIGNE | K18: La réunion | L18: {=INDEX(AAA!C:C,AE18)} -> TROIS BASSINS/ SAINT PAUL | M18: {=INDEX(AAA!G:G,AE18)} -> 97422 | N18: {=INDEX(AAA!B:B,AE18)} -> C | S18: =AAA!L$26 -> crescencevivien@gmail.com | AE18: =D18 -> 26
A19: FK-018 | B19: 46114 | C19: =C18 -> Eco-antibio2 | D19: 57 | E19: {=INDEX(AAA!D:D,AE19)} -> 98615034 | F19: EARL DES ROSES | G19: Morizur Jean Charles | H19: Naisseur-engraisseur | I19: Fayçal Khetim | J19: {=INDEX(AAA!E:E,AE19)} -> 312 CHEMIN DES ROSES | K19: La réunion | L19: {=INDEX(AAA!C:C,AE19)} -> TROIS BASSINS/ SAINT PAUL | M19: {=INDEX(AAA!G:G,AE19)} -> 97435 | N19: {=INDEX(AAA!B:B,AE19)} -> C | S19: {=INDEX(AAA!L:L,AE19)} -> jeancharles974@hotmail.fr | AE19: =D19 -> 57
A20: FK-019 | B20: 46114 | C20: =C19 -> Eco-antibio2 | D20: 102 | E20: {=INDEX(AAA!D:D,AE20)} -> 98715122 | F20: {=INDEX(AAA!A:A,AE20)} -> EARL SOCIETE DU TAN ROUGE | G20: Hoareau Bernard | H20: Naisseur-engraisseur | I20: Fayçal Khetim | J20: {=INDEX(AAA!E:E,AE20)} -> 52 CD 6 CHEMIN D EAU | K20: La réunion | L20: {=INDEX(AAA!C:C,AE20)} -> TROIS BASSINS/ SAINT PAUL | M20: {=INDEX(AAA!G:G,AE20)} -> 97422 | N20: {=INDEX(AAA!B:B,AE20)} -> C | S20: {=INDEX(AAA!L:L,AE20)} -> societedutanrouge@gmail.com | AE20: =D20 -> 102
A21: FK-020 | B21: 46114 | C21: =C20 -> Eco-antibio2 | D21: 94 | E21: {=INDEX(AAA!D:D,AE21)} -> 98915019 | F21: EARL NIDNORG | G21: Grondin Ludovic | H21: Naisseur-engraisseur | I21: Fayçal Khetim | J21: {=INDEX(AAA!E:E,AE21)} -> 68 CHEMIN AUBERVAL | K21: La réunion | L21: {=INDEX(AAA!C:C,AE21)} -> TROIS BASSINS/ SAINT PAUL | M21: {=INDEX(AAA!G:G,AE21)} -> 97435 | N21: {=INDEX(AAA!B:B,AE21)} -> C | S21: {=INDEX(AAA!L:L,AE21)} -> earl.nidnorg@orange.fr | AE21: =D21 -> 94
A22: FK-021 | B22: 46114 | C22: =C21 -> Eco-antibio2 | D22: 22 | E22: {=INDEX(AAA!D:D,AE22)} -> 98315144 | F22: {=INDEX(AAA!A:A,AE22)} -> BOYER YVAN | G22: Boyer Yvan | H22: Naisseur-engraisseur | I22: Fayçal Khetim | J22: {=INDEX(AAA!E:E,AE22)} -> 50 CHEMIN GEVIN | K22: La réunion | L22: {=INDEX(AAA!C:C,AE22)} -> TROIS BASSINS/ SAINT PAUL | M22: {=INDEX(AAA!G:G,AE22)} -> 97411 | N22: {=INDEX(AAA!B:B,AE22)} -> C | S22: yvanboyer974@gmail.com | AE22: =D22 -> 22
A23: FK-022 | B23: 46120 | C23: =C22 -> Eco-antibio2 | D23: 88 | E23: {=INDEX(AAA!D:D,AE23)} -> 98315097 | F23: EARL LES LILAS | G23: Lauret Pierre Robert | H23: Naisseur-engraisseur | I23: Fayçal Khetim | J23: {=INDEX(AAA!E:E,AE23)} -> 205 CHEMIN MARTYR | K23: La réunion | L23: {=INDEX(AAA!C:C,AE23)} -> TROIS BASSINS/ SAINT PAUL | M23: {=INDEX(AAA!G:G,AE23)} -> 97411 | N23: {=INDEX(AAA!B:B,AE23)} -> C | S23: lauretpierre111@gmail.com | AE23: =D23 -> 88
A24: FK-022b | B24: 46121 | C24: =C23 -> Eco-antibio2 | D24: 37 | E24: {=INDEX(AAA!D:D,AE24)} -> 98006064 | F24: EARL ACBA LES JADES | G24: Azor Bernadette | H24: Naisseur-engraisseur | I24: Fayçal Khetim | J24: {=INDEX(AAA!E:E,AE24)} -> 130 RUE CARRON LOUIS | K24: La réunion | L24: {=INDEX(AAA!C:C,AE24)} -> PLAINE DES PALMISTES/ SAINTE ANNE | M24: {=INDEX(AAA!G:G,AE24)} -> 97431 | N24: {=INDEX(AAA!B:B,AE24)} -> C | S24: berazor974@gmail.com | AE24: =D24 -> 37
A25: FK-023 | B25: 46121 | C25: =C23 -> Eco-antibio2 | D25: 160 | E25: {=INDEX(AAA!D:D,AE25)} -> 98006103 | F25: {=INDEX(AAA!A:A,AE25)} -> SCEA ELEVAGE LALLEMAND | G25: Lallemand Olivier | H25: Naisseur-engraisseur | I25: Fayçal Khetim | J25: {=INDEX(AAA!E:E,AE25)} -> 51 RUE LUC BOYER - PETITE PLAINE | K25: La réunion | L25: {=INDEX(AAA!C:C,AE25)} -> PLAINE DES PALMISTES/ SAINTE ANNE | M25: {=INDEX(AAA!G:G,AE25)} -> 97431 | N25: {=INDEX(AAA!B:B,AE25)} -> I | S25: {=INDEX(AAA!L:L,AE25)} -> lallemand431olivier@gmail.com | AE25: =D25 -> 160
A26: FK-024 | B26: 46121 | C26: =C25 -> Eco-antibio2 | D26: 35 | E26: {=INDEX(AAA!D:D,AE26)} -> 98010194 | F26: {=INDEX(AAA!A:A,AE26)} -> DIJOUX THIERRY | G26: Dijoux Thierry | H26: Naisseur-engraisseur | I26: Fayçal Khetim | J26: 288 ROUTE NATIONALE 3 | K26: La réunion | L26: {=INDEX(AAA!C:C,AE26)} -> PLAINE DES PALMISTES/ SAINTE ANNE | M26: 97470 | N26: {=INDEX(AAA!B:B,AE26)} -> C | S26: {=INDEX(AAA!L:L,AE26)} -> dijoux.jean-pascal@orange.fr | AE26: =D26 -> 35
A27: FK-025 | B27: 46121 | C27: =C26 -> Eco-antibio2 | D27: 59 | E27: {=INDEX(AAA!D:D,AE27)} -> 98006154 | F27: {=INDEX(AAA!A:A,AE27)} -> EARL FERME DES ARUMS | G27: Seusse Yannick | H27: Naisseur-engraisseur | I27: Fayçal Khetim | J27: 38 rue des arums | K27: La réunion | L27: {=INDEX(AAA!C:C,AE27)} -> PLAINE DES PALMISTES/ SAINTE ANNE | M27: {=INDEX(AAA!G:G,AE27)} -> 97490 | N27: {=INDEX(AAA!B:B,AE27)} -> C | S27: seusseyannick@gmail.com | AE27: =D27 -> 59
A28: FK-026 | B28: 46122 | C28: =C27 -> Eco-antibio2 | D28: 93 | E28: {=INDEX(AAA!D:D,AE28)} -> 98209034 | F28: {=INDEX(AAA!A:A,AE28)} -> EARL MOUNIAMA ET FILLE | G28: Karine Mouniama | H28: Naisseur-engraisseur | I28: Fayçal Khetim | J28: {=INDEX(AAA!E:E,AE28)} -> 528 CHEMIN CANAL MOREAU | K28: La réunion | L28: {=INDEX(AAA!C:C,AE28)} -> SAINT ANDRE / SAINT BENOIT | M28: {=INDEX(AAA!G:G,AE28)} -> 97440 | N28: {=INDEX(AAA!B:B,AE28)} -> C | S28: kms_mouniama@hotmail.fr | AE28: =D28 -> 93
A29: FK-027 | B29: 46122 | C29: =C28 -> Eco-antibio2 | D29: 11 | E29: {=INDEX(AAA!D:D,AE29)} -> 98009108 | F29: {=INDEX(AAA!A:A,AE29)} -> BANOUBIE RENE | G29: Banoubie Rene | H29: Naisseur-engraisseur | I29: Fayçal Khetim | J29: {=INDEX(AAA!E:E,AE29)} -> 123 ALLEE ZELMAR | K29: La réunion | L29: {=INDEX(AAA!C:C,AE29)} -> SAINT ANDRE / SAINT BENOIT | M29: {=INDEX(AAA!G:G,AE29)} -> 97440 | N29: {=INDEX(AAA!B:B,AE29)} -> C | S29: {=INDEX(AAA!L:L,AE29)} -> rene.banoubie@gmail.com | AE29: =D29 -> 11
A30: FK-028 | B30: 46122 | C30: =C29 -> Eco-antibio2 | D30: 71 | E30: {=INDEX(AAA!D:D,AE30)} -> 98009287 | F30: {=INDEX(AAA!A:A,AE30)} -> EARL LA PARINTA ( ex: SELLIN YVETTE) | G30: D. Vingadassin | H30: Naisseur-engraisseur | I30: Fayçal Khetim | J30: 1610 CHEMIN PATELIN RIVIERE DU MAT LES BATS | K30: La réunion | L30: {=INDEX(AAA!C:C,AE30)} -> SAINT ANDRE / SAINT BENOIT | M30: {=INDEX(AAA!G:G,AE30)} -> 97440 | N30: {=INDEX(AAA!B:B,AE30)} -> C | S30: dede.vinga@gmail.com | AE30: =D30 -> 71
A31: FK-029 | B31: 46122 | C31: =C30 -> Eco-antibio2 | D31: 119 | E31: {=INDEX(AAA!D:D,AE31)} -> 98009107 | F31: GRONDIN MARIE JOSIE REPRO | G31: Grondin marie José | H31: Naisseur-engraisseur | I31: Fayçal Khetim | J31: {=INDEX(AAA!E:E,AE31)} -> 356 CH VALENTIN | K31: La réunion | L31: {=INDEX(AAA!C:C,AE31)} -> SAINT ANDRE / SAINT BENOIT | M31: {=INDEX(AAA!G:G,AE31)} -> 97440 | N31: {=INDEX(AAA!B:B,AE31)} -> I | S31: {=INDEX(AAA!L:L,AE31)} -> elodievivienne.grondin@gmail.com | AE31: =D31 -> 119
A32: FK-029b | B32: 46154 | C32: =C30 -> Eco-antibio2 | D32: 118 | E32: {=INDEX(AAA!D:D,AE32)} -> 98021728 | F32: GRONDIN MARIE JOSIE ENGRAISSEMENT | G32: Grondin marie José | H32: Naisseur-engraisseur | I32: Fayçal Khetim | J32: 3 ALLEE DES CRYPTOMERIAS | K32: La réunion | L32: {=INDEX(AAA!C:C,AE32)} -> SALAZIE | M32: {=INDEX(AAA!G:G,AE32)} -> 97440 | N32: {=INDEX(AAA!B:B,AE32)} -> I | S32: {=INDEX(AAA!L:L,AE32)} -> elodievivienne.grondin@gmail.com | AE32: =D32 -> 118
A33: FK-030 | B33: 46122 | C33: =C32 -> Eco-antibio2 | D33: 77 | E33: {=INDEX(AAA!D:D,AE33)} -> 98102014 | F33: EARL LES ABEILLES | G33: Moreau Linda | H33: Naisseur-engraisseur | I33: Fayçal Khetim | J33: 17 CHEMIN DES PAPANGUES LIBERIA LES HAUTS | K33: La réunion | L33: {=INDEX(AAA!C:C,AE33)} -> SAINT ANDRE / SAINT BENOIT | M33: 97412 | N33: {=INDEX(AAA!B:B,AE33)} -> C | S33: lesabeilles97412@gmail.com | AE33: =D33 -> 77
A34: FK-031 | B34: 46125 | C34: =C33 -> Eco-antibio2 | D34: 58 | E34: {=INDEX(AAA!D:D,AE34)} -> 98004063 | F34: {=INDEX(AAA!A:A,AE34)} -> EARL DU CAP | G34: Sanassy David | H34: Naisseur-engraisseur | I34: Fayçal Khetim | J34: 173 CHEMIN DU CAP | K34: La réunion | L34: {=INDEX(AAA!C:C,AE34)} -> ETANG SALE/SAINT LOUIS | M34: {=INDEX(AAA!G:G,AE34)} -> 97427 | N34: {=INDEX(AAA!B:B,AE34)} -> C | S34: {=INDEX(AAA!L:L,AE34)} -> david.sanassy@hotmail.fr | AE34: =D34 -> 58
A35: FK-032 | B35: 46125 | C35: =C34 -> Eco-antibio2 | D35: 66 | E35: {=INDEX(AAA!D:D,AE35)} -> 98004111 | F35: EARL JOLY FAMILY | G35: Grosset Gille | H35: Naisseur-engraisseur | I35: Fayçal Khetim | J35: {=INDEX(AAA!E:E,AE35)} -> 39 CHEMIN MANIRON | K35: La réunion | L35: {=INDEX(AAA!C:C,AE35)} -> ETANG SALE/SAINT LOUIS | M35: {=INDEX(AAA!G:G,AE35)} -> 97427 | N35: {=INDEX(AAA!B:B,AE35)} -> C | S35: {=INDEX(AAA!L:L,AE35)} -> fortunegrosset@gmail.com | AE35: =D35 -> 66
A36: FK-033 | B36: 46128 | C36: =C35 -> Eco-antibio2 | D36: 54 | E36: {=INDEX(AAA!D:D,AE36)} -> 98214113 | F36: {=INDEX(AAA!A:A,AE36)} -> EARL DES FLAMBOYANTS | G36: Noel Danielle | H36: Naisseur-engraisseur | I36: Fayçal Khetim | J36: {=INDEX(AAA!E:E,AE36)} -> 48 CHEMIN DEJEAN | K36: La réunion | L36: {=INDEX(AAA!C:C,AE36)} -> ETANG SALE/SAINT LOUIS | M36: {=INDEX(AAA!G:G,AE36)} -> 97421 | N36: {=INDEX(AAA!B:B,AE36)} -> C | S36: {=INDEX(AAA!L:L,AE36)} -> mariedanielle.noel@outlook.fr | AE36: =D36 -> 54
A37: FK-034 | B37: 46128 | C37: =C36 -> Eco-antibio2 | D37: 134 | E37: {=INDEX(AAA!D:D,AE37)} -> 98214274 | F37: {=INDEX(AAA!A:A,AE37)} -> LIONI MAXIMIN | G37: Lioni Maximin | H37: Naisseur-engraisseur | I37: Fayçal Khetim | J37: {=INDEX(AAA!E:E,AE37)} -> 57 BIS RUE JULIETTE DODU | K37: La réunion | L37: {=INDEX(AAA!C:C,AE37)} -> ETANG SALE/SAINT LOUIS | M37: {=INDEX(AAA!G:G,AE37)} -> 97421 | N37: {=INDEX(AAA!B:B,AE37)} -> C | S37: {=INDEX(AAA!L:L,AE37)} -> maximinlioni@gmail.com | AE37: =D37 -> 134
A38: FK-035 | B38: 46128 | C38: =C37 -> Eco-antibio2 | D38: 53 | E38: {=INDEX(AAA!D:D,AE38)} -> 98114008 | F38: {=INDEX(AAA!A:A,AE38)} -> EARL DE MONT PLAISIR | G38: Maillot Yves | H38: Naisseur-engraisseur | I38: Fayçal Khetim | J38: {=INDEX(AAA!E:E,AE38)} -> 30 CHEMIN BON ACCEUIL - LES MAKES | K38: La réunion | L38: {=INDEX(AAA!C:C,AE38)} -> ETANG SALE/SAINT LOUIS | M38: {=INDEX(AAA!G:G,AE38)} -> 97421 | N38: {=INDEX(AAA!B:B,AE38)} -> I | S38: emiliemaillot.86@gmail.com | AE38: =D38 -> 53
A39: FK-036 | B39: 46128 | C39: =C38 -> Eco-antibio2 | D39: 45 | E39: {=INDEX(AAA!D:D,AE39)} -> 98214112 | F39: EARL CANNELLE | G39: Roger Daniel | H39: Naisseur-engraisseur | I39: Fayçal Khetim | J39: {=INDEX(AAA!E:E,AE39)} -> 2B RUE LISLET GEOFFROY | K39: La réunion | L39: {=INDEX(AAA!C:C,AE39)} -> ETANG SALE/SAINT LOUIS | M39: {=INDEX(AAA!G:G,AE39)} -> 97421 | N39: {=INDEX(AAA!B:B,AE39)} -> C | S39: {=INDEX(AAA!L:L,AE39)} -> danielrog@wanadoo.fr | AE39: =D39 -> 45
A40: FK-037 | B40: 46129 | C40: =C39 -> Eco-antibio2 | D40: 149 | E40: {=INDEX(AAA!D:D,AE40)} -> 98212047 | F40: {=INDEX(AAA!A:A,AE40)} -> ROBERT HENRI | G40: Robert Henri | H40: Naisseur-engraisseur | I40: Fayçal Khetim | J40: {=INDEX(AAA!E:E,AE40)} -> 17 CHEMIN DES GLYCINES | K40: La réunion | L40: {=INDEX(AAA!C:C,AE40)} -> SAINT JOSEPH | M40: {=INDEX(AAA!G:G,AE40)} -> 97480 | N40: {=INDEX(AAA!B:B,AE40)} -> C | S40: exploitationrobert@gmail.com | AE40: =D40 -> 149
...

Sheet Sheet 1
A1: isolat_ID | B1: contigs | C1: genome_size | D1: N50 | E1: ID-maldi | F1: Score_MALDI | G1: scheme | H1: ST | I1: Confiance-ST | J1: Gambit | K1: allele01 | L1: allele02 | M1: allele03 | N1: allele04 | O1: allele05 | P1: allele06 | Q1: allele07 | R1: aadA1 | S1: aadA5 | T1: aph(3'')-Ib | U1: aph(6)-Id | V1: blaACT | W1: blaACT-109 | X1: blaCTX-M-1 | Y1: blaCTX-M-15 | Z1: blaFONA-7 | AA1: blaIMI-1 | AB1: blaOKP-A | AC1: blaSFDC | AD1: blaSHV-11 | AE1: blaTEM-1 | AF1: dfrA14 | AG1: dfrA17 | AH1: floR | AI1: fosA | AJ1: fosA2 | AK1: mph(A) | AL1: oqxA | AM1: oqxB | AN1: qacL | AO1: qnrS1 | AP1: sul2 | AQ1: sul3 | AR1: tet(A) | AS1: tet(B) | AT1: aadA2 | AU1: ant(3'')-IIa | AV1: aph(3')-Ia | AW1: blaADC | AX1: blaCTX-M | AY1: blaCTX-M-14 | AZ1: blaOCH | BA1: blaOKP-A-11 | BB1: blaOKP-B-2 | BC1: blaOXA | BD1: blaOXY-1-9 | BE1: blaSHV-33 | BF1: catA1 | BG1: catA2 | BH1: cml | BI1: cmlA1 | BJ1: dfrA12 | BK1: oqxA3 | BL1: oqxB19 | BM1: qacEdelta1 | BN1: qnrB1 | BO1: sul1 | BP1: tet(D)
A2: 04FP.B | B2: 14 | C2: 27032772 | D2: 5283956 | E2: Non concluant | F2: 0 | G2: koxytoca | H2: 40 | J2: klebsiella oxytoca | K2: gapA(3) | L2: infB(8) | M2: mdh(20) | N2: pgi(7) | O2: phoE(23) | P2: rpoB(14) | Q2: tonB(18) | R2: plasmid::IncFIA,IncFII,rep_cluster_2183::136228 | T2: plasmid::IncFIB::228851 | U2: plasmid::IncFIB::228851 | Z2: C | AC2: C | AF2: plasmid::IncFIB::228851 | AH2: plasmid::IncFIA,IncFII,rep_cluster_2183::136228 | AI2: C | AN2: plasmid::IncFIA,IncFII,rep_cluster_2183::136228 | AQ2: plasmid::IncFIA,IncFII,rep_cluster_2183::136228 | AR2: plasmid::IncFIA,IncFII,rep_cluster_2183::136228 | AT2: plasmid::IncFIA,IncFII,rep_cluster_2183::136228 | AU2: C | AV2: C | AW2: C | AX2: plasmid::IncFIB::228851 | AY2: plasmid::IncFIA,IncFII,rep_cluster_2183::136228 | AZ2: C | BA2: C | BC2: C | BD2: C | BG2: plasmid::IncFIB::228851 | BH2: C | BI2: plasmid::IncFIA,IncFII,rep_cluster_2183::136228 | BJ2: plasmid::IncFIA,IncFII,rep_cluster_2183::136228 | BN2: plasmid::IncFIB::228851 | BP2: plasmid::IncFIB::228851
A3: 06FP.R | B3: 4 | C3: 5097238 | D3: 4881760 | E3: e-coli | F3: 2.15 | G3: ecoli_achtman_4 | H3: 3268 | J3: e-coli | K3: adk(4) | L3: fumC(26) | M3: gyrB(2) | N3: icd(363) | O3: mdh(5) | P3: purA(5) | Q3: recA(19) | Y3: C | AO3: C
A4: 13FP.B | B4: 2 | C4: 5041539 | D4: 4844996 | E4: enterobacter cloacae complex (enterobacter ludwigii) | F4: 2.43 | G4: ecloacae | H4: 14 | J4: enterobacter cloacae complex (enterobacter asburiae) | K4: dnaA(13) | L4: fusA(2) | M4: gyrB(47) | N4: leuS(23) | O4: pyrG(53) | P4: rplB(2) | Q4: rpoB(14) | W4: C | AJ4: C | AL4: C | AM4: C
A5: 24MP.R | B5: 4 | C5: 5064967 | D5: 4799630 | E5: e-coli | F5: 2.26 | G5: ecoli_achtman_4 | H5: 156 | J5: e-coli | K5: adk(6) | L5: fumC(29) | M5: gyrB(32) | N5: icd(16) | O5: mdh(11) | P5: purA(8) | Q5: recA(44) | S5: plasmid::IncI-gamma/K1::110327 | X5: plasmid::IncI-gamma/K1::110327 | AG5: plasmid::IncI-gamma/K1::110327 | AP5: plasmid::IncI-gamma/K1::110327 | AS5: C
A6: 28FP.R | B6: 2 | C6: 5002360 | D6: 4890216 | F6: 1.33 | G6: ecoli_achtman_4 | H6: 3268 | J6: e-coli | K6: adk(4) | L6: fumC(26) | M6: gyrB(2) | N6: icd(363) | O6: mdh(5) | P6: purA(5) | Q6: recA(19) | Y6: C | AO6: C
A7: 29FP.B | B7: 2 | C7: 4868117 | D7: 4775282 | E7: enterobacter cloacae complex (enterobacter bugandis) | F7: 2.37 | G7: ecloacae | H7: 2706 | J7: enterobacter cloacae complex (enterobacter roggenkampii) | K7: dnaA(381) | L7: fusA(346) | M7: gyrB(522) | N7: leuS(476) | O7: pyrG(199) | P7: rplB(254) | Q7: rpoB(217) | V7: C | AA7: C | AI7: C | AL7: C | AM7: C
A8: 29FP.c | B8: 2 | C8: 4868115 | D8: 4775282 | E8: enterobacter cloacae complex (enterobacter hormaechei) | F8: 1.98 | G8: ecloacae | H8: 2706 | J8: enterobacter cloacae complex (enterobacter roggenkampii) | K8: dnaA(381) | L8: fusA(346) | M8: gyrB(522) | N8: leuS(476) | O8: pyrG(199) | P8: rplB(254) | Q8: rpoB(217) | V8: C | AA8: C | AI8: C | AL8: C | AM8: C
A9: 29FP.R | B9: 3 | C9: 5051203 | D9: 4816911 | E9: e-coli | F9: 2.31 | G9: ecoli_achtman_4 | H9: 58 | J9: e-coli | K9: adk(6) | L9: fumC(4) | M9: gyrB(4) | N9: icd(16) | O9: mdh(24) | P9: purA(8) | Q9: recA(14) | T9: C | U9: C | Y9: C | AE9: C | AO9: C | AP9: C
A10: 34FP.R | B10: 5 | C10: 5203257 | D10: 4848643 | E10: Non concluant | F10: 0 | G10: ecoli_achtman_4 | H10: 58 | J10: e-coli | K10: adk(6) | L10: fumC(4) | M10: gyrB(4) | N10: icd(16) | O10: mdh(24) | P10: purA(8) | Q10: recA(14) | Y10: C | AE10: C | AO10: C | AR10: C
A11: 34MP.R | B11: 8 | C11: 5152191 | D11: 4849008 | E11: e-coli | F11: 2.1 | G11: ecoli_achtman_4 | H11: 58 | J11: e-coli | K11: adk(6) | L11: fumC(4) | M11: gyrB(4) | N11: icd(16) | O11: mdh(24) | P11: purA(8) | Q11: recA(14) | Y11: C | AE11: C | AO11: C | AR11: C
A12: 43FP.B | B12: 2 | C12: 5376648 | D12: 5167309 | E12: Non concluant | F12: 0 | G12: klebsiella | H12: 4083 | J12: klebsiella pneumoniae | K12: gapA(2) | L12: infB(5) | M12: mdh(2) | N12: pgi(1) | O12: phoE(4) | P12: rpoB(1) | Q12: tonB(4) | T12: plasmid::IncFIB::209339 | U12: plasmid::IncFIB::209339 | Y12: plasmid::IncFIB::209339 | AD12: C | AI12: C | AK12: plasmid::IncFIB::209339 | AL12: C | AO12: plasmid::IncFIB::209339 | AP12: plasmid::IncFIB::209339 | AR12: plasmid::IncFIB::209339 | AT12: plasmid::IncFIB::209339 | AV12: plasmid::IncFIB::209339 | BJ12: plasmid::IncFIB::209339 | BL12: C | BM12: plasmid::IncFIB::209339 | BO12: plasmid::IncFIB::209339
A13: 43FP.R | B13: 4 | C13: 4856057 | D13: 4733393 | E13: e-coli | F13: 2.31 | G13: ecoli_achtman_4 | H13: 1598 | J13: e-coli | K13: adk(8) | L13: fumC(7) | M13: gyrB(1) | N13: icd(8) | O13: mdh(8) | P13: purA(13) | Q13: recA(47) | Y13: C | AO13: C | AR13: C
A14: 55FP.B | B14: 2 | C14: 5441692 | D14: 5304786 | E14: klebsiella pneumoniae | F14: 2.26 | G14: klebsiella | H14: 6911 | J14: klebsiella pneumoniae | K14: gapA(17) | L14: infB(19) | M14: mdh(79) | N14: pgi(20) | O14: phoE(150) | P14: rpoB(55) | Q14: tonB(142) | T14: plasmid::IncFIB,IncFII,rep_cluster_2183::136906 | U14: plasmid::IncFIB,IncFII,rep_cluster_2183::136906 | Y14: plasmid::IncFIB,IncFII,rep_cluster_2183::136906 | AB14: C | AE14: plasmid::IncFIB,IncFII,rep_cluster_2183::136906 | AF14: plasmid::IncFIB,IncFII,rep_cluster_2183::136906 | AI14: C | AL14: C | AM14: C | AO14: plasmid::IncFIB,IncFII,rep_cluster_2183::136906 | AP14: plasmid::IncFIB,IncFII,rep_cluster_2183::136906
A15: 62FP.B | B15: 2 | C15: 5917447 | D15: 5842612 | F15: 2.01 | H15: - | J15: serratia fonticola | Z15: C | AC15: C
A16: 68FP.B | B16: 5 | C16: 6357595 | D16: 5983823 | E16: klebsiella oxytoca | F16: 2.36 | G16: koxytoca | H16: 40 | J16: klebsiella oxytoca | K16: gapA(3) | L16: infB(8) | M16: mdh(20) | N16: pgi(7) | O16: phoE(23) | P16: rpoB(14) | Q16: tonB(18) | T16: plasmid::IncFIB::243099 | U16: plasmid::IncFIB::243099 | Y16: plasmid::IncFIB::243099 | AE16: plasmid::IncFIB::243099 | AF16: plasmid::IncFIB::243099 | AL16: C | AM16: C | AP16: plasmid::IncFIB::243099 | AV16: C | BD16: C | BG16: plasmid::IncFIB::243099 | BN16: plasmid::IncFIB::243099 | BP16: plasmid::IncFIB::243099
A17: 78Mfe.R | B17: 47 | C17: 5222421 | D17: 823155 | E17: e-coli | F17: 2.42 | G17: ecoli_achtman_4 | H17: 50 | J17: e-coli | K17: adk(26) | L17: fumC(7) | M17: gyrB(4) | N17: icd(1) | O17: mdh(8) | P17: purA(8) | Q17: recA(6) | Y17: C | AO17: C
A18: 78Mfe.B | B18: 2 | C18: 5635962 | D18: 5414539 | E18: klebsiella pneumoniae | F18: 2.41 | G18: klebsiella | H18: NEW ST1 | J18: klebsiella pneumoniae | K18: gapA(2) | L18: infB(1) | M18: mdh(2) | N18: pgi(1) | O18: phoE(1) | P18: rpoB(1) | Q18: tonB(57) | Y18: plasmid::IncFIB,IncU::221423 | AE18: plasmid::IncFIB,IncU::221423 | AF18: plasmid::IncFIB,IncU::221423 | AI18: C | AM18: C | AO18: plasmid::IncFIB,IncU::221423 | AP18: plasmid::IncFIB,IncU::221423 | BE18: C | BF18: plasmid::IncFIB,IncU::221423 | BK18: C

Sheet Annalyse Facteur de risque
A1: IDENTIFICATION | G1: TAILLE & STRUCTURE | P1: Environnement de l'élevage | AC1: BIOSECURITE | AF1: Mouvements d'animaux | AH1: SANTE | AP1: Antibiotique | BL1: Hygiène et désinfection
A2: Elevage_ID | B2: Zone_géographique | C2: Date | D2: Bactérie résistante | F2: Age Charcutier (en semaine) | G2: Nb_batiment | H2: Type _batiment | I2: Type_elevage | J2: Nb_porcs | K2: Nb_Truie | L2: Nb_verrats | M2: Nb_bandes | N2: annee_installation | O2: Age_Elevage | P2: Distance_Eau_Inf100m | Q2: Type_pointH2O | R2: Elevage_Porcin_Inf500m | S2: Elevage_Autre_Espece_Inf500m | T2: Type_elevage_proche | U2: Autre animaux dans l'elevage | AC2: Marche_Avant | AD2: Isolement_Malades | AE2: Duree_Quarantaine (jours) | AF2: Achat_Animaux | AG2: Provenance_Exterieure | AH2: visite_veto | AI2: patho_digestive | AJ2: patho_respiratoire | AK2: patho_urinaire | AL2: Boiterie | AM2: patho_cutanee | AN2: Patho_repro | AO2: Canibalisme | AP2: Type_traitement | AQ2: Frequence_atb (x/mois) | AR2: Elimination atb | AS2: atb_penicilline (Benzylpénicilline + Dihydrostreptomycine) + Dihydrostreptomycine) | AV2: atb_amoxicilline | AY2: atb_phénicolés | BA2: atb_sulfamides | BC2: atb_Lincosamides | BE2: atb_macrolide | BH2: atb_Pleuromutilines | BJ2: atb_Tétracyclines | BL2: Utilisation_Desinfectant | BM2: Nom_Desinfectant | BN2: Alternance | BO2: Utilisation_Detergent | BP2: Nom_Detergent
D3: E-BSL | E3: E-CP | U3: Bovin | V3: Ovin/Caprin | W3: Volaille | X3: Chien/chat | Y3: Lapin | Z3: Equidé | AA3: Oiseau | AB3: Péroquet | AS3: Oui/Non | AT3: Shotapen | AU3: Pénijectyl | AV3: Oui/Non | AW3: Kelamoxyl | AX3: Vétrimoxin | AY3: Oui/Non | AZ3: Florfénicol | BA3: Oui/Non | BB3: Sulfacycline | BC3: Oui/Non | BD3: Lincospectin | BE3: Oui/Non | BF3: PHARMASIN | BG3: HUVEXXIN | BH3: Oui/Non | BI3: VETMULIN | BJ3: Oui/Non | BK3: LABIMYCIN
A4: FK001 | B4: =Elevage!L2 -> SAINT JOSEPH | C4: =Elevage!B2 -> 46092 | D4: 0 | E4: 0 | G4: 2 | H4: Dynamique | I4: Naisseur-engraisseur | J4: 700 | K4: 50 | L4: 2 | M4: 7 | N4: 1995 | O4: =2026-N4 -> 31 | P4: 0 | Q4: N.A | R4: 0 | S4: 1 | T4: Bovin | U4: 1 | V4: 0 | W4: 1 | X4: 0 | Y4: 0 | Z4: 0 | AA4: 0 | AB4: 0 | AC4: Partiel | AD4: Oui | AE4: 45 | AF4: 1 | AG4: SDC, NDP | AH4: Annuelle | AI4: 0 | AJ4: 1 | AK4: 0 | AL4: 0 | AM4: 0 | AN4: 0 | AO4: 0 | AP4: Individuelle | AQ4: 1 | AR4: DASRI | AS4: =IF(OR(AT4=1,AU4=1),1,0) -> 1 | AT4: 1 | AU4: 0 | AV4: =IF(OR(AW4=1,AX4),1,0) -> 1 | AW4: 1 | AX4: 0 | AY4: =IF(OR(AZ4=1),1,0) -> 0 | AZ4: 0 | BA4: =IF(OR(BB4=1),1,0) -> 0 | BB4: 0 | BC4: =IF(OR(BD4=1),1,0) -> 0 | BD4: 0 | BE4: =IF(OR(BG4=1,BF4),1,0) -> 0 | BF4: 0 | BG4: 0 | BH4: =IF(OR(BI4=1),1,0) -> 0 | BI4: 0 | BJ4: =IF(OR(BK4=1),1,0) -> 0 | BK4: 0 | BL4: 1 | BM4: G3F, G5F,Evogerme | BN4: 1 | BO4: 1 | BP4: Decabase, Evoclean
A5: FK002 | B5: =Elevage!L3 -> SAINT JOSEPH | C5: =Elevage!B3 -> 46092 | D5: 0 | E5: 0 | G5: 1 | H5: Statique | I5: Naisseur-engraisseur | J5: 400 | K5: 32 | L5: 2 | M5: 3 | N5: 1997 | O5: =2026-N5 -> 29 | P5: 0 | Q5: N.A | R5: 1 | S5: 1 | T5: Bovin, Caprin, Volaille | U5: 0 | V5: 0 | W5: 0 | X5: 0 | Y5: 0 | Z5: 0 | AA5: 0 | AB5: 0 | AC5: Oui | AD5: Oui | AE5: 40 | AF5: 1 | AG5: HKC | AH5: occsionnelle | AI5: 1 | AJ5: 1 | AK5: 0 | AL5: 0 | AM5: 0 | AN5: 0 | AO5: 0 | AP5: Individuelle | AQ5: 2 à 3 | AR5: DASRI | AS5: =IF(OR(AT5=1,AU5=1),1,0) -> 1 | AT5: 1 | AU5: 0 | AV5: =IF(OR(AW5=1,AX5),1,0) -> 0 | AW5: 0 | AX5: 0 | AY5: =IF(OR(AZ5=1),1,0) -> 0 | AZ5: 0 | BA5: =IF(OR(BB5=1),1,0) -> 1 | BB5: 1 | BC5: =IF(OR(BD5=1),1,0) -> 0 | BD5: 0 | BE5: =IF(OR(BG5=1,BF5),1,0) -> 1 | BF5: 0 | BG5: 1 | BH5: =IF(OR(BI5=1),1,0) -> 0 | BI5: 0 | BJ5: =IF(OR(BK5=1),1,0) -> 0 | BK5: 0 | BL5: 1 | BM5: Sanifarm | BN5: 0 | BO5: 1 | BP5: Lypoclean
A6: FK003 | B6: =Elevage!L4 -> SAINT PIERRE / PETITE ILE | C6: =Elevage!B4 -> 46094 | D6: 0 | E6: 0 | G6: 2 | H6: Mixte | I6: Naisseur-engraisseur | J6: 400 | K6: 38 | L6: 2 | M6: 7 | N6: 1993 | O6: =2026-N6 -> 33 | P6: 0 | Q6: N.A | R6: 0 | S6: 0 | T6: N.A | U6: 0 | V6: 1 | W6: 1 | X6: 1 | Y6: 0 | Z6: 0 | AA6: 0 | AB6: 0 | AC6: Non | AD6: Oui | AE6: 45 | AF6: 1 | AG6: NDP | AH6: occsionnelle | AI6: 1 | AJ6: 1 | AK6: 1 | AL6: 0 | AM6: 0 | AN6: 0 | AO6: 0 | AP6: Individuelle | AQ6: 2 à 3 | AR6: DASRI | AS6: =IF(OR(AT6=1,AU6=1),1,0) -> 1 | AT6: 1 | AU6: 0 | AV6: =IF(OR(AW6=1,AX6),1,0) -> 0 | AW6: 0 | AX6: 0 | AY6: =IF(OR(AZ6=1),1,0) -> 1 | AZ6: 1 | BA6: =IF(OR(BB6=1),1,0) -> 0 | BB6: 0 | BC6: =IF(OR(BD6=1),1,0) -> 0 | BD6: 0 | BE6: =IF(OR(BG6=1,BF6),1,0) -> 1 | BF6: 0 | BG6: 1 | BH6: =IF(OR(BI6=1),1,0) -> 0 | BI6: 0 | BJ6: =IF(OR(BK6=1),1,0) -> 0 | BK6: 0 | BL6: 1 | BM6: Sanifarm | BN6: 1 | BP6: Lypoclean
A7: FK004 | B7: =Elevage!L5 -> SAINT PIERRE / PETITE ILE | C7: =Elevage!B5 -> 46099 | D7: 1 | E7: 0 | G7: 1 | H7: Dynamique | I7: Naisseur-engraisseur | J7: 440 | K7: 32 | L7: 1 | M7: 5 | N7: 2024 | O7: =2026-N7 -> 2 | P7: 0 | Q7: N.A | R7: 1 | S7: 1 | T7: Bovin, Volaille | U7: 0 | V7: 0 | W7: 0 | X7: 0 | Y7: 0 | Z7: 0 | AA7: 0 | AB7: 0 | AC7: Oui | AD7: Oui | AE7: 45 | AF7: 1 | AG7: Francisceas | AH7: Annuelle | AI7: 0 | AJ7: 0 | AK7: 0 | AL7: 0 | AM7: 0 | AN7: 0 | AO7: 0 | AP7: Mixte | AQ7: 1 | AR7: DASRI | AS7: =IF(OR(AT7=1,AU7=1),1,0) -> 1 | AT7: 1 | AU7: 0 | AV7: =IF(OR(AW7=1,AX7),1,0) -> 1 | AW7: 0 | AX7: 1 | AY7: =IF(OR(AZ7=1),1,0) -> 0 | AZ7: 0 | BA7: =IF(OR(BB7=1),1,0) -> 0 | BB7: 0 | BC7: =IF(OR(BD7=1),1,0) -> 1 | BD7: 1 | BE7: =IF(OR(BG7=1,BF7),1,0) -> 0 | BF7: 0 | BG7: 0 | BH7: =IF(OR(BI7=1),1,0) -> 0 | BI7: 0 | BJ7: =IF(OR(BK7=1),1,0) -> 0 | BK7: 0 | BL7: 1 | BM7: Spectragene, Evogerme | BN7: 1 | BO7: 1 | BP7: Fomax
A8: FK005 | B8: =Elevage!L6 -> ETANG SALE/SAINT LOUIS | C8: =Elevage!B6 -> 46106 | D8: 0 | E8: 0 | F8: 26 | G8: 1 | H8: Mixte | I8: Naisseur-engraisseur | J8: 425 | K8: 38 | L8: 1 | M8: 6 | N8: 1990 | O8: =2026-N8 -> 36 | P8: 0 | Q8: N.A | R8: 0 | S8: 1 | T8: Caprin | U8: 0 | V8: 0 | W8: 0 | X8: 1 | Y8: 0 | Z8: 0 | AA8: 0 | AB8: 0 | AC8: Oui | AD8: Oui | AE8: 40 | AF8: 1 | AG8: Francisceas | AH8: Annuelle | AI8: 0 | AJ8: 1 | AK8: 0 | AL8: 0 | AM8: 0 | AN8: 0 | AO8: 0 | AP8: Mixte | AQ8: 1 | AR8: DASRI | AS8: =IF(OR(AT8=1,AU8=1),1,0) -> 1 | AT8: 1 | AU8: 0 | AV8: =IF(OR(AW8=1,AX8),1,0) -> 1 | AW8: 0 | AX8: 1 | AY8: =IF(OR(AZ8=1),1,0) -> 1 | AZ8: 1 | BA8: =IF(OR(BB8=1),1,0) -> 0 | BB8: 0 | BC8: =IF(OR(BD8=1),1,0) -> 0 | BD8: 0 | BE8: =IF(OR(BG8=1,BF8),1,0) -> 0 | BF8: 0 | BG8: 0 | BH8: =IF(OR(BI8=1),1,0) -> 0 | BI8: 0 | BJ8: =IF(OR(BK8=1),1,0) -> 0 | BK8: 0 | BL8: 1 | BM8: Spectragene, Vulcan, Sidving | BN8: 1 | BO8: 1 | BP8: (CPPR)
A9: FK006 | B9: =Elevage!L7 -> ETANG SALE/SAINT LOUIS | C9: =Elevage!B7 -> 46106 | D9: 1 | E9: 0 | F9: 23 | G9: 1 | H9: Dynamique | I9: Naisseur-engraisseur | J9: 200 | K9: 16 | L9: 1 | M9: 4 | N9: 1996 | O9: =2026-N9 -> 30 | P9: 0 | Q9: N.A | R9: 0 | S9: 1 | T9: Bovin | U9: 1 | V9: 0 | W9: 0 | X9: 1 | Y9: 0 | Z9: 0 | AA9: 0 | AB9: 0 | AC9: Partiel | AD9: Oui | AE9: 40 | AF9: 1 | AG9: Ferme du Bonheur | AH9: Annuelle | AI9: 1 | AJ9: 1 | AK9: 0 | AL9: 1 | AM9: 0 | AN9: 0 | AO9: 0 | AP9: Individuelle | AQ9: 1 | AR9: DASRI | AS9: =IF(OR(AT9=1,AU9=1),1,0) -> 1 | AT9: 1 | AU9: 0 | AV9: =IF(OR(AW9=1,AX9),1,0) -> 0 | AW9: 0 | AX9: 0 | AY9: =IF(OR(AZ9=1),1,0) -> 0 | AZ9: 0 | BA9: =IF(OR(BB9=1),1,0) -> 0 | BB9: 0 | BC9: =IF(OR(BD9=1),1,0) -> 0 | BD9: 0 | BE9: =IF(OR(BG9=1,BF9),1,0) -> 0 | BF9: 0 | BG9: 0 | BH9: =IF(OR(BI9=1),1,0) -> 0 | BI9: 0 | BJ9: =IF(OR(BK9=1),1,0) -> 0 | BK9: 0 | BL9: 1 | BM9: Halamide | BN9: 0 | BO9: 0 | BP9: EAU
A10: FK007 | B10: =Elevage!L8 -> AVIRONS/ SAINT LEU | C10: =Elevage!B8 -> 46111 | D10: 0 | E10: 0 | G10: 1 | H10: Dynamique | I10: Naisseur-engraisseur | J10: 600 | K10: 45 | L10: 1 | M10: 4 | N10: 1990 | O10: =2026-N10 -> 36 | P10: 0 | Q10: N.A | R10: 1 | S10: 1 | T10: Volaille | U10: 0 | V10: 0 | W10: 0 | X10: 0 | Y10: 0 | Z10: 0 | AA10: 0 | AB10: 0 | AC10: Oui | AD10: Partiel | AE10: 40 | AF10: 1 | AG10: HKC | AH10: Annuelle | AI10: 0 | AJ10: 1 | AK10: 1 | AL10: 1 | AM10: 0 | AN10: 0 | AO10: 0 | AP10: Mixte | AR10: Autre | AS10: =IF(OR(AT10=1,AU10=1),1,0) -> 1 | AT10: 1 | AU10: 1 | AV10: =IF(OR(AW10=1,AX10),1,0) -> 1 | AW10: 0 | AX10: 1 | AY10: =IF(OR(AZ10=1),1,0) -> 1 | AZ10: 1 | BA10: =IF(OR(BB10=1),1,0) -> 0 | BB10: 0 | BC10: =IF(OR(BD10=1),1,0) -> 0 | BD10: 0 | BE10: =IF(OR(BG10=1,BF10),1,0) -> 0 | BF10: 0 | BG10: 0 | BH10: =IF(OR(BI10=1),1,0) -> 0 | BI10: 0 | BJ10: =IF(OR(BK10=1),1,0) -> 0 | BK10: 0 | BL10: 1 | BM10: Spectragene, Vulcan, Sidving | BN10: 1 | BO10: 1 | BP10: Decabase, Fomax
A11: FK008 | B11: =Elevage!L9 -> AVIRONS/ SAINT LEU | C11: =Elevage!B9 -> 46111 | D11: 0 | E11: 0 | F11: 22 | G11: 2 | H11: Dynamique | I11: Naisseur-engraisseur | J11: 400 | K11: 38 | L11: 1 | M11: 5 | N11: 1992 | O11: =2026-N11 -> 34 | P11: 0 | Q11: N.A | R11: 1 | S11: 1 | T11: Volaille | U11: 0 | V11: 0 | W11: 1 | X11: 0 | Y11: 0 | Z11: 0 | AA11: 0 | AB11: 0 | AC11: Oui | AD11: Oui | AE11: 40 | AF11: 1 | AG11: Francisceas | AH11: Frequente | AI11: 1 | AJ11: 1 | AK11: 0 | AL11: 0 | AM11: 1 | AN11: 0 | AO11: 0 | AP11: Individuelle | AQ11: +3 | AR11: DASRI | AS11: =IF(OR(AT11=1,AU11=1),1,0) -> 1 | AT11: 1 | AU11: 0 | AV11: =IF(OR(AW11=1,AX11),1,0) -> 1 | AW11: 0 | AX11: 1 | AY11: =IF(OR(AZ11=1),1,0) -> 1 | AZ11: 1 | BA11: =IF(OR(BB11=1),1,0) -> 0 | BB11: 0 | BC11: =IF(OR(BD11=1),1,0) -> 0 | BD11: 0 | BE11: =IF(OR(BG11=1,BF11),1,0) -> 0 | BF11: 0 | BG11: 0 | BH11: =IF(OR(BI11=1),1,0) -> 0 | BI11: 0 | BJ11: =IF(OR(BK11=1),1,0) -> 0 | BK11: 0 | BL11: 0 | BM11: EAU | BN11: 0 | BO11: 1 | BP11: Fomax
A12: FK009 | B12: =Elevage!L10 -> AVIRONS/ SAINT LEU | C12: =Elevage!B10 -> 46111 | D12: 0 | E12: 0 | F12: 22 | G12: 1 | H12: Dynamique | I12: Naisseur-engraisseur | J12: 400 | K12: 32 | L12: 1 | M12: 5 | N12: 1995 | O12: =2026-N12 -> 31 | P12: 0 | Q12: N.A | R12: 1 | S12: 0 | T12: N.A | U12: 0 | V12: 0 | W12: 0 | X12: 0 | Y12: 0 | Z12: 0 | AA12: 0 | AB12: 0 | AC12: Non | AD12: Oui | AE12: 40 | AF12: 1 | AG12: Francisceas | AH12: Annuelle | AI12: 0 | AJ12: 1 | AK12: 0 | AL12: 1 | AM12: 0 | AN12: 0 | AO12: 0 | AP12: Mixte | AR12: DASRI | AS12: =IF(OR(AT12=1,AU12=1),1,0) -> 1 | AT12: 1 | AU12: 0 | AV12: =IF(OR(AW12=1,AX12),1,0) -> 1 | AW12: 0 | AX12: 1 | AY12: =IF(OR(AZ12=1),1,0) -> 0 | AZ12: 0 | BA12: =IF(OR(BB12=1),1,0) -> 0 | BB12: 0 | BC12: =IF(OR(BD12=1),1,0) -> 1 | BD12: 1 | BE12: =IF(OR(BG12=1,BF12),1,0) -> 0 | BF12: 0 | BG12: 0 | BH12: =IF(OR(BI12=1),1,0) -> 0 | BI12: 0 | BJ12: =IF(OR(BK12=1),1,0) -> 0 | BK12: 0 | BL12: 1 | BM12: Virocide | BN12: 0 | BO12: 1 | BP12: Evoclean
A13: FK010 | B13: =Elevage!L11 -> AVIRONS/ SAINT LEU | C13: =Elevage!B11 -> 46111 | D13: 0 | E13: 0 | F13: 26 | G13: 1 | H13: Dynamique | I13: Naisseur-engraisseur | J13: 400 | K13: 35 | L13: 1 | M13: 5 | N13: 2011 | O13: =2026-N13 -> 15 | P13: 0 | Q13: N.A | R13: 1 | S13: 1 | T13: Bovin, Volaille | U13: 0 | V13: 0 | W13: 0 | X13: 0 | Y13: 0 | Z13: 0 | AA13: 0 | AB13: 0 | AC13: Oui | AD13: Oui | AE13: 45 | AF13: 1 | AG13: Francisceas | AH13: Annuelle | AI13: 0 | AJ13: 1 | AK13: 1 | AL13: 0 | AM13: 0 | AN13: 0 | AO13: 0 | AP13: Mixte | AQ13: 2 à 3 | AR13: DASRI | AS13: =IF(OR(AT13=1,AU13=1),1,0) -> 1 | AT13: 1 | AU13: 0 | AV13: =IF(OR(AW13=1,AX13),1,0) -> 1 | AW13: 0 | AX13: 1 | AY13: =IF(OR(AZ13=1),1,0) -> 0 | AZ13: 0 | BA13: =IF(OR(BB13=1),1,0) -> 0 | BB13: 0 | BC13: =IF(OR(BD13=1),1,0) -> 0 | BD13: 0 | BE13: =IF(OR(BG13=1,BF13),1,0) -> 0 | BF13: 0 | BG13: 0 | BH13: =IF(OR(BI13=1),1,0) -> 0 | BI13: 0 | BJ13: =IF(OR(BK13=1),1,0) -> 0 | BK13: 0 | BL13: 1 | BM13: Spectragene | BN13: 0 | BO13: 1 | BP13: Fomax
A14: FK011 | B14: =Elevage!L12 -> AVIRONS/ SAINT LEU | C14: =Elevage!B12 -> 46112 | D14: 0 | E14: 0 | F14: 25 | G14: 1 | H14: Dynamique | I14: Naisseur-engraisseur | J14: 450 | K14: 32 | L14: 1 | M14: 5 | N14: 2000 | O14: =2026-N14 -> 26 | P14: 0 | Q14: N.A | R14: 0 | S14: 0 | T14: N.A | U14: 0 | V14: 0 | W14: 0 | X14: 0 | Y14: 0 | Z14: 0 | AA14: 0 | AB14: 0 | AC14: Oui | AD14: Oui | AE14: 40 | AF14: 1 | AG14: Francisceas | AH14: Annuelle | AI14: 0 | AJ14: 1 | AK14: 1 | AL14: 0 | AM14: 1 | AN14: 0 | AO14: 1 | AP14: Mixte | AQ14: 1 | AR14: DASRI | AS14: =IF(OR(AT14=1,AU14=1),1,0) -> 1 | AT14: 1 | AU14: 0 | AV14: =IF(OR(AW14=1,AX14),1,0) -> 1 | AW14: 0 | AX14: 1 | AY14: =IF(OR(AZ14=1),1,0) -> 1 | AZ14: 1 | BA14: =IF(OR(BB14=1),1,0) -> 0 | BB14: 0 | BC14: =IF(OR(BD14=1),1,0) -> 0 | BD14: 0 | BE14: =IF(OR(BG14=1,BF14),1,0) -> 1 | BF14: 0 | BG14: 1 | BH14: =IF(OR(BI14=1),1,0) -> 0 | BI14: 0 | BJ14: =IF(OR(BK14=1),1,0) -> 0 | BK14: 0 | BL14: 1 | BM14: CD20 | BN14: 0 | BO14: 1 | BP14: Cleanovea
A15: FK012 | B15: =Elevage!L13 -> AVIRONS/ SAINT LEU | C15: =Elevage!B13 -> 46112 | D15: 0 | E15: 0 | F15: 24 | G15: 1 | H15: Mixte | I15: Naisseur-engraisseur | J15: 320 | K15: 42 | L15: 1 | M15: 6 | N15: 1997 | O15: =2026-N15 -> 29 | P15: 0 | Q15: N.A | R15: 0 | S15: 0 | T15: N.A | U15: 0 | V15: 0 | W15: 0 | X15: 0 | Y15: 0 | Z15: 0 | AA15: 0 | AB15: 0 | AC15: Partiel | AD15: Oui | AE15: 40 | AF15: 1 | AG15: Francisceas | AH15: Annuelle | AI15: 0 | AJ15: 0 | AK15: 1 | AL15: 1 | AM15: 1 | AN15: 0 | AO15: 1 | AP15: Mixte | AR15: DASRI | AS15: =IF(OR(AT15=1,AU15=1),1,0) -> 1 | AT15: 1 | AU15: 0 | AV15: =IF(OR(AW15=1,AX15),1,0) -> 0 | AW15: 0 | AX15: 0 | AY15: =IF(OR(AZ15=1),1,0) -> 0 | AZ15: 0 | BA15: =IF(OR(BB15=1),1,0) -> 0 | BB15: 0 | BC15: =IF(OR(BD15=1),1,0) -> 0 | BD15: 0 | BE15: =IF(OR(BG15=1,BF15),1,0) -> 0 | BF15: 0 | BG15: 0 | BH15: =IF(OR(BI15=1),1,0) -> 0 | BI15: 0 | BJ15: =IF(OR(BK15=1),1,0) -> 0 | BK15: 0 | BL15: 1 | BM15: Spectragene | BN15: 0 | BO15: 0 | BP15: EAU
A16: FK013 | B16: =Elevage!L14 -> AVIRONS/ SAINT LEU | C16: =Elevage!B14 -> 46112 | D16: 1 | E16: 0 | F16: 26 | G16: 1 | H16: Dynamique | I16: Naisseur-engraisseur | J16: 750 | K16: 80 | L16: 1 | M16: 7 | N16: 1990 | O16: =2026-N16 -> 36 | P16: 1 | Q16: Retenue colinaire | R16: 0 | S16: 1 | T16: Bovin | U16: 0 | V16: 0 | W16: 0 | X16: 0 | Y16: 0 | Z16: 0 | AA16: 0 | AB16: 0 | AC16: Non | AD16: Oui | AE16: 40 | AF16: 1 | AG16: Francisceas | AH16: Annuelle | AI16: 1 | AJ16: 1 | AK16: 0 | AL16: 1 | AM16: 0 | AN16: 0 | AO16: 0 | AP16: Mixte | AQ16: 2 à 3 | AR16: DASRI | AS16: =IF(OR(AT16=1,AU16=1),1,0) -> 1 | AT16: 1 | AU16: 0 | AV16: =IF(OR(AW16=1,AX16),1,0) -> 1 | AW16: 0 | AX16: 1 | AY16: =IF(OR(AZ16=1),1,0) -> 0 | AZ16: 0 | BA16: =IF(OR(BB16=1),1,0) -> 0 | BB16: 0 | BC16: =IF(OR(BD16=1),1,0) -> 0 | BD16: 0 | BE16: =IF(OR(BG16=1,BF16),1,0) -> 0 | BF16: 0 | BG16: 0 | BH16: =IF(OR(BI16=1),1,0) -> 0 | BI16: 0 | BJ16: =IF(OR(BK16=1),1,0) -> 0 | BK16: 0 | BL16: 1 | BM16: Spectragene ,Virocide | BN16: 1 | BO16: 1 | BP16: Decabase
